<?xml version="1.0" encoding="utf-8"?>
<!-- This URDF was automatically created by SolidWorks to URDF Exporter! Originally created by Stephen Brawner (brawner@gmail.com) 
     Commit Version: 1.6.0-4-g7f85cfe  Build Version: 1.6.7995.38578
     For more information, please see http://wiki.ros.org/sw_urdf_exporter -->
<robot
  name="pineapple v1.1">
  <mujoco>
    <compiler
      meshdir="../meshes"
      balanceinertia="true"
      discardvisual="false" />
  </mujoco>
  <link
    name="base_link">
    <inertial>  
      <origin
        xyz="0.03425855 0.00006357 0.07778567"
        rpy="0 0 0" />
      <mass
        value="2.99" />
      <inertia
        ixx="0.01519872"
        ixy="0.000007367"
        ixz="0.00256248"
        iyy="0.02158004"
        iyz="-0.00001102"
        izz="0.02428081" />
    </inertial>
    <visual>
      <origin
        xyz="0 0 0"
        rpy="0 0 0" />
      <geometry>
        <mesh
          filename="package://pineapple v1.1/meshes/base_link.STL" />
      </geometry>
      <material
        name="">
        <color
          rgba="0.1451 0.1451 0.1451 1" />
      </material>
    </visual>
    <collision>
      <origin
        xyz="0.0075 0 0.05"
        rpy="0 0 0" />
      <geometry>
        <box size="0.255 0.1 0.1"/>
      </geometry>
    </collision>
    <collision>
      <origin
        xyz="-0.0285 0 0.130"
        rpy="0 0 0" />
      <geometry>
        <box size="0.213 0.125 0.06"/>
      </geometry>
    </collision>
    <collision>
      <origin
        xyz="0.078 -0.075 0.05"
        rpy="0 0 0" />
      <geometry>
        <box size="0.05 0.05 0.1"/>
      </geometry>
    </collision>
    <collision>
      <origin
        xyz="0.078 0.075 0.05"
        rpy="0 0 0" />
      <geometry>
        <box size="0.05 0.05 0.1"/>
      </geometry>
    </collision>
  </link>
  <link
    name="battery">
    <inertial>
      <origin
        xyz="-0.095007 -3.4328E-06 0.093415"
        rpy="0 0 0" />
      <mass
        value="0.64" />
      <inertia
        ixx="0.00147269"
        ixy="0.0"
        ixz="0.00003683"
        iyy="0.00136181"
        iyz="0.00000013"
        izz="0.00038215" />
    </inertial>
    <visual>
      <origin
        xyz="0 0 0"
        rpy="0 0 0" />
      <geometry>
        <mesh
          filename="package://pineapple v1.1/meshes/battery.STL" />
      </geometry>
      <material
        name="">
        <color
          rgba="0.53725 0.53725 0.53725 1" />
      </material>
    </visual>
  </link>
  <joint
    name="battery_fix"
    type="fixed">
    <origin
      xyz="0 0 0"
      rpy="0 0 0" />
    <parent
      link="base_link" />
    <child
      link="battery" />
    <axis
      xyz="0 0 0" />
  </joint>
  <link
    name="R_hip">
    <inertial>
      <origin
        xyz="-0.054201 0.0016168 0.00050585"
        rpy="0 0 0" />
      <mass
        value="0.585" />
      <inertia
        ixx="0.00045956"
        ixy="0.00000742"
        ixz="-0.00000128"
        iyy="0.00077661"
        iyz="0.00000917"
        izz="0.00050968" />
    </inertial>
    <visual>
      <origin
        xyz="0 0 0"
        rpy="0 0 0" />
      <geometry>
        <mesh
          filename="package://pineapple v1.1/meshes/R_hip.STL" />
      </geometry>
      <material
        name="">
        <color
          rgba="1 1 1 1" />
      </material>
    </visual>
  </link>
  <joint
    name="R_hip_joint"
    type="revolute">
    <origin
      xyz="0.047159 -0.06125 0.066001"
      rpy="0 0 0" />
    <parent
      link="base_link" />
    <child
      link="R_hip" />
    <axis
      xyz="1 0 0" />
    <limit
      lower="-0.17444"
      upper="0.52358"
      effort="23.7"
      velocity="30.1" />
  </joint>
  <link
    name="R_thigh">
    <inertial>
      <origin
        xyz="-0.0014005 -0.015871 -0.13295"
        rpy="0 0 0" />
      <mass
        value="0.911" />
      <inertia
        ixx="0.00359239"
        ixy="0.00001718"
        ixz="0.00000539"
        iyy="0.00399866"
        iyz="0.00016395"
        izz="0.00085307" />
    </inertial>
    <visual>
      <origin
        xyz="0 0 0"
        rpy="0 0 0" />
      <geometry>
        <mesh
          filename="package://pineapple v1.1/meshes/R_thigh.STL" />
      </geometry>
      <material
        name="">
        <color
          rgba="0.098039 0.098039 0.098039 1" />
      </material>
    </visual>
    <collision>
      <origin
        xyz="0.0003 -0.0095 -0.049"
        rpy="0 0 0" />
      <geometry>
       <box size="0.055 0.019 0.12"/>
      </geometry>
    </collision>
    <collision>
      <origin
        xyz="0 -0.0175 -0.165"
        rpy="1.57 0 0" />
      <geometry>
       <cylinder radius="0.0515" length="0.035"/>
      </geometry>
    </collision>
  </link>
  <joint
    name="R_thigh_joint"
    type="revolute">
    <origin
      xyz="-0.05675 -0.01995 0"
      rpy="0 0 0" />
    <parent
      link="R_hip" />
    <child
      link="R_thigh" />
    <axis
      xyz="0 1 0" />
    <limit
      lower="0"
      upper="1.57"
      effort="23.7"
      velocity="30.1" />
  </joint>
  <link
    name="R_calf">
    <inertial>
      <origin
        xyz="-7.3779E-05 -0.014526 -0.11981"
        rpy="0 0 0" />
      <mass
        value="0.567" />
      <inertia
        ixx="0.00246258"
        ixy="-0.00000032"
        ixz="-0.00000235"
        iyy="0.00252067"
        iyz="0.00007208"
        izz="0.00022736"  />
    </inertial>
    <visual>
      <origin
        xyz="0 0 0"
        rpy="0 0 0" />
      <geometry>
        <mesh
          filename="package://pineapple v1.1/meshes/R_calf.STL" />
      </geometry>
      <material
        name="">
        <color
          rgba="0.1451 0.1451 0.1451 1" />
      </material>
    </visual>
    <collision>
      <origin
        xyz="-0.0006 -0.0118 -0.0465"
        rpy="0 0 0" />
      <geometry>
        <box size="0.048 0.0236 0.093"/>
      </geometry>
    </collision>
  </link>
  <joint
    name="R_calf_joint"
    type="revolute">
    <origin
      xyz="0 -0.0383 -0.165"
      rpy="0 0 0" />
    <parent
      link="R_thigh" />
    <child
      link="R_calf" />
    <axis
      xyz="0 1 0" />
    <limit
      lower="-3.141"
      upper="0"
      effort="23.7"
      velocity="30.1" />
  </joint>
  <link
    name="R_wheel">
    <inertial>
      <origin
        xyz="2.8013E-11 -0.0095126 -9.34E-11"
        rpy="0 0 0" />
      <mass
        value="0.35" />
      <inertia
        ixx="0.00056018"
        ixy="0"
        ixz="0"
        iyy="0.00108926"
        iyz="0"
        izz="0.00056018" />
    </inertial>
    <visual>
      <origin
        xyz="0 0 0"
        rpy="0 0 0" />
      <geometry>
        <mesh
          filename="package://pineapple v1.1/meshes/R_wheel.STL" />
      </geometry>
      <material
        name="">
        <color
          rgba="0.15294 0.15294 0.15294 1" />
      </material>
    </visual>
    <collision>
      <origin
        xyz="0 -0.0085 0"
        rpy="1.57 0 0" />
      <geometry>
        <cylinder radius="0.07" length="0.023"/>
      </geometry>
    </collision>
  </link>
  <joint
    name="R_wheel_joint"
    type="continuous">
    <origin
      xyz="0 -0.02705 -0.165"
      rpy="0 0 0" />
    <parent
      link="R_calf" />
    <child
      link="R_wheel" />
    <axis
      xyz="0 1 0" />
    <limit
      effort="3.69"
      velocity="60" />
  </joint>
  <link
    name="L_hip">
    <inertial>
      <origin
        xyz="-0.054201 -0.0016168 0.00050585"
        rpy="0 0 0" />
      <mass
        value="0.585" />
      <inertia
        ixx="0.00045956"
        ixy="-0.00000742"
        ixz="-0.00000128"
        iyy="0.00077661"
        iyz="0.00000917"
        izz="0.00050968"/>
    </inertial>
    <visual>
      <origin
        xyz="0 0 0"
        rpy="0 0 0" />
      <geometry>
        <mesh
          filename="package://pineapple v1.1/meshes/L_hip.STL" />
      </geometry>
      <material
        name="">
        <color
          rgba="1 1 1 1" />
      </material>
    </visual>
  </link>
  <joint
    name="L_hip_joint"
    type="revolute">
    <origin
      xyz="0.047159 0.06125 0.066001"
      rpy="0 0 0" />
    <parent
      link="base_link" />
    <child
      link="L_hip" />
    <axis
      xyz="1 0 0" />
    <limit
      lower="-0.52358"
      upper="0.17444"
      effort="23.7"
      velocity="30.1" />
  </joint>
  <link
    name="L_thigh">
    <inertial>
      <origin
        xyz="-0.0014005 0.015871 -0.13295"
        rpy="0 0 0" />
      <mass
        value="0.911" />
      <inertia
        ixx="0.00359239"
        ixy="0.00001718"
        ixz="-0.00000539"
        iyy="0.00399866"
        iyz="0.00016395"
        izz="0.00085307" />
    </inertial>
    <visual>
      <origin
        xyz="0 0 0"
        rpy="0 0 0" />
      <geometry>
        <mesh
          filename="package://pineapple v1.1/meshes/L_thigh.STL" />
      </geometry>
      <material
        name="">
        <color
          rgba="0.098039 0.098039 0.098039 1" />
      </material>
    </visual>
    <collision>
      <origin
        xyz="0.0003 0.0095 -0.049"
        rpy="0 0 0" />
      <geometry>
       <box size="0.055 0.019 0.12"/>
      </geometry>
    </collision>
    <collision>
      <origin
        xyz="0 0.0175 -0.165"
        rpy="1.57 0 0" />
      <geometry>
       <cylinder radius="0.0515" length="0.035"/>
      </geometry>
    </collision>
  </link>
  <joint
    name="L_thigh_joint"
    type="revolute">
    <origin
      xyz="-0.05675 0.01995 0"
      rpy="0 0 0" />
    <parent
      link="L_hip" />
    <child
      link="L_thigh" />
    <axis
      xyz="0 1 0" />
    <limit
      lower="0"
      upper="1.57"
      effort="23.7"
      velocity="30.1" />
  </joint>
  <link
    name="L_calf">
    <inertial>
      <origin
        xyz="-7.3933E-05 0.014526 -0.11981"
        rpy="0 0 0" />
      <mass
        value="0.567" />
      <inertia
        ixx="0.00246258"
        ixy="-0.00000032"
        ixz="0.00000235"
        iyy="0.00252067"
        iyz="0.00007208"
        izz="0.00022736" />
    </inertial>
    <visual>
      <origin
        xyz="0 0 0"
        rpy="0 0 0" />
      <geometry>
        <mesh
          filename="package://pineapple v1.1/meshes/L_calf.STL" />
      </geometry>
      <material
        name="">
        <color
          rgba="0.1451 0.1451 0.1451 1" />
      </material>
    </visual>
    <collision>
      <origin
        xyz="-0.0006 0.0118 -0.0465"
        rpy="0 0 0" />
      <geometry>
        <box size="0.048 0.0236 0.093"/>
      </geometry>
    </collision>
  </link>
  <joint
    name="L_calf_joint"
    type="revolute">
    <origin
      xyz="0 0.0383 -0.165"
      rpy="0 0 0" />
    <parent
      link="L_thigh" />
    <child
      link="L_calf" />
    <axis
      xyz="0 1 0" />
    <limit
      lower="-3.141"
      upper="0"
      effort="23.7"
      velocity="30.1" />
  </joint>
  <link
    name="L_wheel">
    <inertial>
      <origin
        xyz="2.7442E-11 0.0095126 -9.3096E-11"
        rpy="0 0 0" />
      <mass
        value="0.35" />
      <inertia
        ixx="0.00056018"
        ixy="0"
        ixz="0"
        iyy="0.00108926"
        iyz="0"
        izz="0.00056018" />
    </inertial>
    <visual>
      <origin
        xyz="0 0 0"
        rpy="0 0 0" />
      <geometry>
        <mesh
          filename="package://pineapple v1.1/meshes/L_wheel.STL" />
      </geometry>
      <material
        name="">
        <color
          rgba="0.15294 0.15294 0.15294 1" />
      </material>
    </visual>
    <collision>
      <origin
        xyz="0 0.0085 0"
        rpy="1.57 0 0" />
      <geometry>
        <cylinder radius="0.07" length="0.023"/>
      </geometry>
    </collision>
  </link>
  <joint
    name="L_wheel_joint"
    type="continuous">
    <origin
      xyz="0 0.02705 -0.165"
      rpy="0 0 0" />
    <parent
      link="L_calf" />
    <child
      link="L_wheel" />
    <axis
      xyz="0 1 0" />
    <limit
      effort="3.69"
      velocity="60" />
  </joint>
</robot>